{
  "Launchpad": "https://bugs.launchpad.net/bugs/1499297",
  "Id": "1499297",
  "Gerrit": "https://review.openstack.org/227701",
  "IdGerrit": "227701",
  "IdCommit": "d7658f60e7664a382472059b947c4f112083466a",
  "Files": [
    "cinder/tests/unit/test_cloudbyte.py",
    "cinder/volume/drivers/cloudbyte/cloudbyte.py"
  ],
  "Lines_Inseted": 52,
  "Lines_Deleted": 4,
  "CommitParent": "57d01641941fe210bc15e85d1e449023b578fa55",
  "Classification": "Bug",
  "KeywordsTitle": "fix, ",
  "Description": "currently does not update, error , difficult task, failure",
  "KeywordsCommit": "fix ,  added , new , solve",
  "Comments": "logic bug"
}