{"Launchpad":"https://bugs.launchpad.net/bugs/1443970","Id":"1443970","Gerrit":"https://review.openstack.org/198385","IdGerrit":"198385","IdCommit":"4908d46d86430db462f5292971975dc22bbe2171","Files":["nova/network/manager.py","nova/tests/unit/network/test_manager.py"],"Lines_Inseted":2,"Lines_Deleted":4,"CommitParent":"d22167e08388f6f557484e469ab559255cc273c2","Classification":"Bug","KeywordsTitle":"networks with wrong dhcp_server in DB","Description":"dhcp_server' values are wrong, ariable 'enable_dhcp' is incorrectly used in loop","KeywordsCommit":"Fixed incorrect dhcp_server value,","Comments":"."}